<?xml version="1.0" ?>
<robot name="cube">

  <link name="baseLink">

    <inertial>
      <origin rpy="0 0 0" xyz="0 0 0"/>
       <mass value="1.0"/>
       <inertia ixx="1" ixy="1" ixz="1" iyy="1" iyz="1" izz="1"/>
    </inertial>

<!--     <visual>
      <origin rpy="0 0 0" xyz="0 0 -0.2"/>
      <geometry>
        <mesh filename="cube.obj" scale="0.2 0.2 0.2"/>
      </geometry>
       <material name="white">
        <color rgba="0.5 0.5 0.5 1"/>
      </material>
    </visual>
 -->
<!--     <collision>
      <origin rpy="0 0 0" xyz="0 0 -0.2"/>
      <geometry>
         <box size="0.02 0.02 0.02"/>
      </geometry>
    </collision> -->


  </link>

<!-- #################################################################################### angularDamping-->
  <joint name="joint1" type="prismatic">
    <!-- <origin xyz="0 0 1" rpy="0 0 3.1416"/> -->
    <axis xyz="0 0 1"/>
    <parent link="baseLink"/>
    <child link="link2"/>
    <calibration rising="0.0"/>
    <dynamics damping="0.0" friction="0.0" linearDamping="0.0" />
    <limit effort="30" velocity="1.0" lower="0" upper="0.2" />
    <!-- <safety_controller k_velocity="10" k_position="15" soft_lower_limit="-2.0" soft_upper_limit="0.5" /> -->
  </joint>


<!-- #################################################################################### -->
  <link name="link2">

    <inertial>
      <origin rpy="0 0 0" xyz="0 0 0"/>
       <mass value="1.0"/>
       <inertia ixx="1" ixy="1" ixz="1" iyy="1" iyz="1" izz="1"/>
    </inertial>

<!--     <visual>
      <origin rpy="0 0 0" xyz="0 0 0"/>
      <geometry>
        <mesh filename="cube.obj" scale="0.3 0.3 0.1"/>
      </geometry>
       <material name="white">
        <color rgba="0.3 0.3 0.3 1"/>
      </material>
    </visual> -->

<!--     <collision>
      <origin rpy="0 0 0" xyz="0 0 0"/>
      <geometry>
         <box size="0.02 0.02 0.02"/>
      </geometry>
    </collision>
 -->

  </link>


<!-- #################################################################################### -->
  <joint name="joint2" type="revolute">
    <axis xyz="1 0 0"/>
    <parent link="link2"/>
    <child link="link3"/>
    <dynamics damping="0.0" friction="0.0"/>
    <limit effort="30" lower="-0.785" upper="0.785" />
  </joint>

<!-- #################################################################################### -->
  <link name="link3">

    <inertial>
      <origin rpy="0 0 0" xyz="0 0 0"/>
       <mass value="1.0"/>
       <inertia ixx="1" ixy="1" ixz="1" iyy="1" iyz="1" izz="1"/>
    </inertial>

<!--     <visual>
      <origin rpy="0 0 0" xyz="0 0 0"/>
      <geometry>
        <mesh filename="cube.obj" scale="0.2 0.2 0.2"/>
      </geometry>
       <material name="grey">
        <color rgba="0.6 0.6 0.6 0.8"/>
      </material>
    </visual> -->

  </link>

<!-- ####################################################################################1.57 -->
  <joint name="joint3" type="revolute">
    <axis xyz="0 1 0"/>
    <parent link="link3"/>
    <child link="platform"/>
    <dynamics damping="0.0" friction="0.0"/>
    <limit effort="30" lower="-0.785" upper="0.785" />
  </joint>


<!-- #################################################################################### -->
  <link name="platform">

    <contact>
      <lateral_friction value="1.0"/>
      <rolling_friction value="0.0"/>
      <restitution value="1.0"/>
    </contact>


    <inertial>
      <origin rpy="0 0 0" xyz="0 0 0"/>
       <mass value="1.0"/>
       <inertia ixx="1" ixy="0" ixz="0" iyy="1" iyz="0" izz="1"/>
    </inertial>


    <visual>
      <origin rpy="0 0 0" xyz="0 0 0"/>
      <geometry>
				<mesh filename="cube.obj" scale="0.3 0.3 0.01"/>
      </geometry>
       <material name="white">
        <color rgba="1 1 1 1"/>
      </material>
    </visual>


    <collision>
      <origin rpy="0 0 0" xyz="0 0 0"/>
      <geometry>
	 	     <box size="0.3 0.3 0.01"/>
      </geometry>
    </collision>

  </link>
</robot>

